[2023-11-23T06:00:01.778+0000] {taskinstance.py:1165} INFO - Dependencies all met for <TaskInstance: rand_user.upload_data_to_destination manual__2023-11-23T05:59:51.572059+00:00 [queued]>
[2023-11-23T06:00:01.790+0000] {taskinstance.py:1165} INFO - Dependencies all met for <TaskInstance: rand_user.upload_data_to_destination manual__2023-11-23T05:59:51.572059+00:00 [queued]>
[2023-11-23T06:00:01.791+0000] {taskinstance.py:1362} INFO - 
--------------------------------------------------------------------------------
[2023-11-23T06:00:01.791+0000] {taskinstance.py:1363} INFO - Starting attempt 1 of 3
[2023-11-23T06:00:01.791+0000] {taskinstance.py:1364} INFO - 
--------------------------------------------------------------------------------
[2023-11-23T06:00:01.805+0000] {taskinstance.py:1383} INFO - Executing <Task(GenericTransfer): upload_data_to_destination> on 2023-11-23 05:59:51.572059+00:00
[2023-11-23T06:00:01.811+0000] {standard_task_runner.py:55} INFO - Started process 5543 to run task
[2023-11-23T06:00:01.815+0000] {standard_task_runner.py:82} INFO - Running: ['***', 'tasks', 'run', 'rand_user', 'upload_data_to_destination', 'manual__2023-11-23T05:59:51.572059+00:00', '--job-id', '452', '--raw', '--subdir', 'DAGS_FOLDER/predictions.py', '--cfg-path', '/tmp/tmp4_a0kjxe']
[2023-11-23T06:00:01.817+0000] {standard_task_runner.py:83} INFO - Job 452: Subtask upload_data_to_destination
[2023-11-23T06:00:01.885+0000] {task_command.py:376} INFO - Running <TaskInstance: rand_user.upload_data_to_destination manual__2023-11-23T05:59:51.572059+00:00 [running]> on host f71f95879a41
[2023-11-23T06:00:01.954+0000] {taskinstance.py:1592} INFO - Exporting the following env vars:
AIRFLOW_CTX_DAG_OWNER=Gaurav
AIRFLOW_CTX_DAG_ID=rand_user
AIRFLOW_CTX_TASK_ID=upload_data_to_destination
AIRFLOW_CTX_EXECUTION_DATE=2023-11-23T05:59:51.572059+00:00
AIRFLOW_CTX_TRY_NUMBER=1
AIRFLOW_CTX_DAG_RUN_ID=manual__2023-11-23T05:59:51.572059+00:00
[2023-11-23T06:00:01.964+0000] {base.py:71} INFO - Using connection ID 'source_db_***' for task execution.
[2023-11-23T06:00:02.160+0000] {base.py:71} INFO - Using connection ID 'dest_conn_id' for task execution.
[2023-11-23T06:00:02.344+0000] {generic_transfer.py:76} INFO - Extracting data from source_db_***
[2023-11-23T06:00:02.344+0000] {generic_transfer.py:77} INFO - Executing: 
 
            INSERT INTO rand_dest_users
            SELECT DISTINCT ON (ru.uuid) ru.*
            FROM rand_users ru
            LEFT JOIN rand_dest_users rdu ON ru.uuid = rdu.uuid
            WHERE rdu.uuid IS NULL
            
[2023-11-23T06:00:02.352+0000] {base.py:71} INFO - Using connection ID 'source_db_***' for task execution.
[2023-11-23T06:00:02.364+0000] {taskinstance.py:1851} ERROR - Task failed with exception
Traceback (most recent call last):
  File "/home/airflow/.local/lib/python3.7/site-packages/airflow/operators/generic_transfer.py", line 85, in execute
    results = get_records(self.sql)
  File "/home/airflow/.local/lib/python3.7/site-packages/airflow/providers/common/sql/hooks/sql.py", line 217, in get_records
    cur.execute(sql)
psycopg2.errors.UndefinedTable: relation "rand_dest_users" does not exist
LINE 2:             INSERT INTO rand_dest_users
                                ^

[2023-11-23T06:00:02.375+0000] {taskinstance.py:1406} INFO - Marking task as UP_FOR_RETRY. dag_id=rand_user, task_id=upload_data_to_destination, execution_date=20231123T055951, start_date=20231123T060001, end_date=20231123T060002
[2023-11-23T06:00:02.387+0000] {standard_task_runner.py:105} ERROR - Failed to execute job 452 for task upload_data_to_destination (relation "rand_dest_users" does not exist
LINE 2:             INSERT INTO rand_dest_users
                                ^
; 5543)
[2023-11-23T06:00:02.426+0000] {local_task_job.py:164} INFO - Task exited with return code 1
[2023-11-23T06:00:02.447+0000] {local_task_job.py:273} INFO - 0 downstream tasks scheduled from follow-on schedule check
