[2023-11-10T09:20:07.469+0000] {taskinstance.py:1165} INFO - Dependencies all met for <TaskInstance: rand_user.process_user manual__2023-11-10T09:19:58.473910+00:00 [queued]>
[2023-11-10T09:20:07.489+0000] {taskinstance.py:1165} INFO - Dependencies all met for <TaskInstance: rand_user.process_user manual__2023-11-10T09:19:58.473910+00:00 [queued]>
[2023-11-10T09:20:07.489+0000] {taskinstance.py:1362} INFO - 
--------------------------------------------------------------------------------
[2023-11-10T09:20:07.490+0000] {taskinstance.py:1363} INFO - Starting attempt 1 of 3
[2023-11-10T09:20:07.491+0000] {taskinstance.py:1364} INFO - 
--------------------------------------------------------------------------------
[2023-11-10T09:20:07.519+0000] {taskinstance.py:1383} INFO - Executing <Task(PythonOperator): process_user> on 2023-11-10 09:19:58.473910+00:00
[2023-11-10T09:20:07.530+0000] {standard_task_runner.py:55} INFO - Started process 2170 to run task
[2023-11-10T09:20:07.539+0000] {standard_task_runner.py:82} INFO - Running: ['***', 'tasks', 'run', 'rand_user', 'process_user', 'manual__2023-11-10T09:19:58.473910+00:00', '--job-id', '133', '--raw', '--subdir', 'DAGS_FOLDER/predictions.py', '--cfg-path', '/tmp/tmpcd24n462']
[2023-11-10T09:20:07.543+0000] {standard_task_runner.py:83} INFO - Job 133: Subtask process_user
[2023-11-10T09:20:07.652+0000] {task_command.py:376} INFO - Running <TaskInstance: rand_user.process_user manual__2023-11-10T09:19:58.473910+00:00 [running]> on host 91f7624ceef9
[2023-11-10T09:20:07.771+0000] {taskinstance.py:1592} INFO - Exporting the following env vars:
AIRFLOW_CTX_DAG_OWNER=Gaurav
AIRFLOW_CTX_DAG_ID=rand_user
AIRFLOW_CTX_TASK_ID=process_user
AIRFLOW_CTX_EXECUTION_DATE=2023-11-10T09:19:58.473910+00:00
AIRFLOW_CTX_TRY_NUMBER=1
AIRFLOW_CTX_DAG_RUN_ID=manual__2023-11-10T09:19:58.473910+00:00
[2023-11-10T09:20:07.795+0000] {taskinstance.py:1851} ERROR - Task failed with exception
Traceback (most recent call last):
  File "/home/airflow/.local/lib/python3.7/site-packages/airflow/operators/python.py", line 175, in execute
    return_value = self.execute_callable()
  File "/home/airflow/.local/lib/python3.7/site-packages/airflow/operators/python.py", line 193, in execute_callable
    return self.python_callable(*self.op_args, **self.op_kwargs)
  File "/opt/airflow/dags/predictions.py", line 14, in _process_user
    user = user_data['results'][0]
KeyError: 'results'
[2023-11-10T09:20:07.809+0000] {taskinstance.py:1406} INFO - Marking task as UP_FOR_RETRY. dag_id=rand_user, task_id=process_user, execution_date=20231110T091958, start_date=20231110T092007, end_date=20231110T092007
[2023-11-10T09:20:07.829+0000] {standard_task_runner.py:105} ERROR - Failed to execute job 133 for task process_user ('results'; 2170)
[2023-11-10T09:20:07.868+0000] {local_task_job.py:164} INFO - Task exited with return code 1
[2023-11-10T09:20:07.912+0000] {local_task_job.py:273} INFO - 0 downstream tasks scheduled from follow-on schedule check
