[2023-11-22T09:12:35.398+0000] {taskinstance.py:1165} INFO - Dependencies all met for <TaskInstance: rand_user.is_api_available manual__2023-11-22T09:12:31.342628+00:00 [queued]>
[2023-11-22T09:12:35.411+0000] {taskinstance.py:1165} INFO - Dependencies all met for <TaskInstance: rand_user.is_api_available manual__2023-11-22T09:12:31.342628+00:00 [queued]>
[2023-11-22T09:12:35.411+0000] {taskinstance.py:1362} INFO - 
--------------------------------------------------------------------------------
[2023-11-22T09:12:35.412+0000] {taskinstance.py:1363} INFO - Starting attempt 1 of 3
[2023-11-22T09:12:35.412+0000] {taskinstance.py:1364} INFO - 
--------------------------------------------------------------------------------
[2023-11-22T09:12:35.430+0000] {taskinstance.py:1383} INFO - Executing <Task(HttpSensor): is_api_available> on 2023-11-22 09:12:31.342628+00:00
[2023-11-22T09:12:35.439+0000] {standard_task_runner.py:55} INFO - Started process 3374 to run task
[2023-11-22T09:12:35.445+0000] {standard_task_runner.py:82} INFO - Running: ['***', 'tasks', 'run', 'rand_user', 'is_api_available', 'manual__2023-11-22T09:12:31.342628+00:00', '--job-id', '50', '--raw', '--subdir', 'DAGS_FOLDER/predictions.py', '--cfg-path', '/tmp/tmp_iio935c']
[2023-11-22T09:12:35.447+0000] {standard_task_runner.py:83} INFO - Job 50: Subtask is_api_available
[2023-11-22T09:12:35.521+0000] {task_command.py:376} INFO - Running <TaskInstance: rand_user.is_api_available manual__2023-11-22T09:12:31.342628+00:00 [running]> on host f71f95879a41
[2023-11-22T09:12:35.619+0000] {taskinstance.py:1592} INFO - Exporting the following env vars:
AIRFLOW_CTX_DAG_OWNER=Gaurav
AIRFLOW_CTX_DAG_ID=rand_user
AIRFLOW_CTX_TASK_ID=is_api_available
AIRFLOW_CTX_EXECUTION_DATE=2023-11-22T09:12:31.342628+00:00
AIRFLOW_CTX_TRY_NUMBER=1
AIRFLOW_CTX_DAG_RUN_ID=manual__2023-11-22T09:12:31.342628+00:00
[2023-11-22T09:12:35.620+0000] {http.py:120} INFO - Poking: api/
[2023-11-22T09:12:35.643+0000] {taskinstance.py:1851} ERROR - Task failed with exception
Traceback (most recent call last):
  File "/home/airflow/.local/lib/python3.7/site-packages/airflow/sensors/base.py", line 189, in execute
    poke_return = self.poke(context)
  File "/home/airflow/.local/lib/python3.7/site-packages/airflow/providers/http/sensors/http.py", line 135, in poke
    raise exc
  File "/home/airflow/.local/lib/python3.7/site-packages/airflow/providers/http/sensors/http.py", line 126, in poke
    extra_options=self.extra_options,
  File "/home/airflow/.local/lib/python3.7/site-packages/airflow/providers/http/hooks/http.py", line 128, in run
    session = self.get_conn(headers)
  File "/home/airflow/.local/lib/python3.7/site-packages/airflow/providers/http/hooks/http.py", line 82, in get_conn
    conn = self.get_connection(self.http_conn_id)
  File "/home/airflow/.local/lib/python3.7/site-packages/airflow/hooks/base.py", line 70, in get_connection
    conn = Connection.get_connection_from_secrets(conn_id)
  File "/home/airflow/.local/lib/python3.7/site-packages/airflow/models/connection.py", line 432, in get_connection_from_secrets
    raise AirflowNotFoundException(f"The conn_id `{conn_id}` isn't defined")
airflow.exceptions.AirflowNotFoundException: The conn_id `rand_user` isn't defined
[2023-11-22T09:12:35.649+0000] {taskinstance.py:1406} INFO - Marking task as UP_FOR_RETRY. dag_id=rand_user, task_id=is_api_available, execution_date=20231122T091231, start_date=20231122T091235, end_date=20231122T091235
[2023-11-22T09:12:35.663+0000] {standard_task_runner.py:105} ERROR - Failed to execute job 50 for task is_api_available (The conn_id `rand_user` isn't defined; 3374)
[2023-11-22T09:12:35.695+0000] {local_task_job.py:164} INFO - Task exited with return code 1
[2023-11-22T09:12:35.725+0000] {local_task_job.py:273} INFO - 0 downstream tasks scheduled from follow-on schedule check
