[2023-11-22T09:50:14.359+0000] {taskinstance.py:1165} INFO - Dependencies all met for <TaskInstance: Data_transfer.store_user manual__2023-11-22T09:49:03.883353+00:00 [queued]>
[2023-11-22T09:50:14.380+0000] {taskinstance.py:1165} INFO - Dependencies all met for <TaskInstance: Data_transfer.store_user manual__2023-11-22T09:49:03.883353+00:00 [queued]>
[2023-11-22T09:50:14.380+0000] {taskinstance.py:1362} INFO - 
--------------------------------------------------------------------------------
[2023-11-22T09:50:14.381+0000] {taskinstance.py:1363} INFO - Starting attempt 2 of 3
[2023-11-22T09:50:14.381+0000] {taskinstance.py:1364} INFO - 
--------------------------------------------------------------------------------
[2023-11-22T09:50:14.420+0000] {taskinstance.py:1383} INFO - Executing <Task(PythonOperator): store_user> on 2023-11-22 09:49:03.883353+00:00
[2023-11-22T09:50:14.430+0000] {standard_task_runner.py:55} INFO - Started process 5332 to run task
[2023-11-22T09:50:14.439+0000] {standard_task_runner.py:82} INFO - Running: ['***', 'tasks', 'run', 'Data_transfer', 'store_user', 'manual__2023-11-22T09:49:03.883353+00:00', '--job-id', '118', '--raw', '--subdir', 'DAGS_FOLDER/data_transfer.py', '--cfg-path', '/tmp/tmpo7eabkjd']
[2023-11-22T09:50:14.443+0000] {standard_task_runner.py:83} INFO - Job 118: Subtask store_user
[2023-11-22T09:50:14.562+0000] {task_command.py:376} INFO - Running <TaskInstance: Data_transfer.store_user manual__2023-11-22T09:49:03.883353+00:00 [running]> on host f71f95879a41
[2023-11-22T09:50:14.669+0000] {taskinstance.py:1592} INFO - Exporting the following env vars:
AIRFLOW_CTX_DAG_OWNER=Gaurav
AIRFLOW_CTX_DAG_ID=Data_transfer
AIRFLOW_CTX_TASK_ID=store_user
AIRFLOW_CTX_EXECUTION_DATE=2023-11-22T09:49:03.883353+00:00
AIRFLOW_CTX_TRY_NUMBER=2
AIRFLOW_CTX_DAG_RUN_ID=manual__2023-11-22T09:49:03.883353+00:00
[2023-11-22T09:50:14.672+0000] {postgres.py:129} INFO - Running copy expert: COPY table1_users FROM stdin WITH DELIMITER as ',', filename: /tmp/rand_processed_user.csv
[2023-11-22T09:50:14.685+0000] {base.py:71} INFO - Using connection ID 'postgres' for task execution.
[2023-11-22T09:50:14.693+0000] {taskinstance.py:1851} ERROR - Task failed with exception
Traceback (most recent call last):
  File "/home/airflow/.local/lib/python3.7/site-packages/airflow/operators/python.py", line 175, in execute
    return_value = self.execute_callable()
  File "/home/airflow/.local/lib/python3.7/site-packages/airflow/operators/python.py", line 193, in execute_callable
    return self.python_callable(*self.op_args, **self.op_kwargs)
  File "/opt/airflow/dags/data_transfer.py", line 39, in _store_user
    filename='/tmp/rand_processed_user.csv'
  File "/home/airflow/.local/lib/python3.7/site-packages/airflow/providers/postgres/hooks/postgres.py", line 137, in copy_expert
    cur.copy_expert(sql, file)
psycopg2.errors.UniqueViolation: duplicate key value violates unique constraint "table1_users_pkey"
DETAIL:  Key (uuid)=(dc5b9a98-cd4a-49f2-b1b3-72e32ca82123) already exists.
CONTEXT:  COPY table1_users, line 1

[2023-11-22T09:50:14.706+0000] {taskinstance.py:1406} INFO - Marking task as UP_FOR_RETRY. dag_id=Data_transfer, task_id=store_user, execution_date=20231122T094903, start_date=20231122T095014, end_date=20231122T095014
[2023-11-22T09:50:14.723+0000] {standard_task_runner.py:105} ERROR - Failed to execute job 118 for task store_user (duplicate key value violates unique constraint "table1_users_pkey"
DETAIL:  Key (uuid)=(dc5b9a98-cd4a-49f2-b1b3-72e32ca82123) already exists.
CONTEXT:  COPY table1_users, line 1
; 5332)
[2023-11-22T09:50:14.768+0000] {local_task_job.py:164} INFO - Task exited with return code 1
[2023-11-22T09:50:14.803+0000] {local_task_job.py:273} INFO - 0 downstream tasks scheduled from follow-on schedule check
