[2023-11-21T12:21:03.344+0000] {taskinstance.py:1165} INFO - Dependencies all met for <TaskInstance: rand_user.Create_table scheduled__2023-11-20T00:00:00+00:00 [queued]>
[2023-11-21T12:21:03.368+0000] {taskinstance.py:1165} INFO - Dependencies all met for <TaskInstance: rand_user.Create_table scheduled__2023-11-20T00:00:00+00:00 [queued]>
[2023-11-21T12:21:03.370+0000] {taskinstance.py:1362} INFO - 
--------------------------------------------------------------------------------
[2023-11-21T12:21:03.370+0000] {taskinstance.py:1363} INFO - Starting attempt 3 of 3
[2023-11-21T12:21:03.371+0000] {taskinstance.py:1364} INFO - 
--------------------------------------------------------------------------------
[2023-11-21T12:21:03.421+0000] {taskinstance.py:1383} INFO - Executing <Task(PostgresOperator): Create_table> on 2023-11-20 00:00:00+00:00
[2023-11-21T12:21:03.438+0000] {standard_task_runner.py:55} INFO - Started process 554 to run task
[2023-11-21T12:21:03.451+0000] {standard_task_runner.py:82} INFO - Running: ['***', 'tasks', 'run', 'rand_user', 'Create_table', 'scheduled__2023-11-20T00:00:00+00:00', '--job-id', '541', '--raw', '--subdir', 'DAGS_FOLDER/predictions.py', '--cfg-path', '/tmp/tmpma420acy']
[2023-11-21T12:21:03.456+0000] {standard_task_runner.py:83} INFO - Job 541: Subtask Create_table
[2023-11-21T12:21:03.659+0000] {task_command.py:376} INFO - Running <TaskInstance: rand_user.Create_table scheduled__2023-11-20T00:00:00+00:00 [running]> on host 91f7624ceef9
[2023-11-21T12:21:03.857+0000] {taskinstance.py:1592} INFO - Exporting the following env vars:
AIRFLOW_CTX_DAG_OWNER=Gaurav
AIRFLOW_CTX_DAG_ID=rand_user
AIRFLOW_CTX_TASK_ID=Create_table
AIRFLOW_CTX_EXECUTION_DATE=2023-11-20T00:00:00+00:00
AIRFLOW_CTX_TRY_NUMBER=3
AIRFLOW_CTX_DAG_RUN_ID=scheduled__2023-11-20T00:00:00+00:00
[2023-11-21T12:21:03.884+0000] {base.py:71} INFO - Using connection ID 'source_db_***' for task execution.
[2023-11-21T12:21:03.889+0000] {taskinstance.py:1851} ERROR - Task failed with exception
Traceback (most recent call last):
  File "/home/airflow/.local/lib/python3.7/site-packages/airflow/providers/postgres/operators/postgres.py", line 94, in execute
    self.hook.run(self.sql, self.autocommit, parameters=self.parameters)
  File "/home/airflow/.local/lib/python3.7/site-packages/airflow/providers/common/sql/hooks/sql.py", line 288, in run
    with closing(self.get_conn()) as conn:
  File "/home/airflow/.local/lib/python3.7/site-packages/airflow/providers/postgres/hooks/postgres.py", line 115, in get_conn
    self.conn = psycopg2.connect(**conn_args)
  File "/home/airflow/.local/lib/python3.7/site-packages/psycopg2/__init__.py", line 122, in connect
    conn = _connect(dsn, connection_factory=connection_factory, **kwasync)
psycopg2.OperationalError: connection to server at "10.226.80.35", port 5445 failed: Network is unreachable
	Is the server running on that host and accepting TCP/IP connections?

[2023-11-21T12:21:03.910+0000] {taskinstance.py:1406} INFO - Marking task as FAILED. dag_id=rand_user, task_id=Create_table, execution_date=20231120T000000, start_date=20231121T122103, end_date=20231121T122103
[2023-11-21T12:21:03.941+0000] {standard_task_runner.py:105} ERROR - Failed to execute job 541 for task Create_table (connection to server at "10.226.80.35", port 5445 failed: Network is unreachable
	Is the server running on that host and accepting TCP/IP connections?
; 554)
[2023-11-21T12:21:03.978+0000] {local_task_job.py:164} INFO - Task exited with return code 1
[2023-11-21T12:21:04.059+0000] {local_task_job.py:273} INFO - 0 downstream tasks scheduled from follow-on schedule check
