[2023-11-10T09:14:57.026+0000] {taskinstance.py:1165} INFO - Dependencies all met for <TaskInstance: rand_user.process_user scheduled__2023-11-09T00:00:00+00:00 [queued]>
[2023-11-10T09:14:57.044+0000] {taskinstance.py:1165} INFO - Dependencies all met for <TaskInstance: rand_user.process_user scheduled__2023-11-09T00:00:00+00:00 [queued]>
[2023-11-10T09:14:57.045+0000] {taskinstance.py:1362} INFO - 
--------------------------------------------------------------------------------
[2023-11-10T09:14:57.045+0000] {taskinstance.py:1363} INFO - Starting attempt 3 of 3
[2023-11-10T09:14:57.046+0000] {taskinstance.py:1364} INFO - 
--------------------------------------------------------------------------------
[2023-11-10T09:14:57.072+0000] {taskinstance.py:1383} INFO - Executing <Task(PythonOperator): process_user> on 2023-11-09 00:00:00+00:00
[2023-11-10T09:14:57.081+0000] {standard_task_runner.py:55} INFO - Started process 1932 to run task
[2023-11-10T09:14:57.089+0000] {standard_task_runner.py:82} INFO - Running: ['***', 'tasks', 'run', 'rand_user', 'process_user', 'scheduled__2023-11-09T00:00:00+00:00', '--job-id', '128', '--raw', '--subdir', 'DAGS_FOLDER/predictions.py', '--cfg-path', '/tmp/tmpk4s9ncpl']
[2023-11-10T09:14:57.092+0000] {standard_task_runner.py:83} INFO - Job 128: Subtask process_user
[2023-11-10T09:14:57.199+0000] {task_command.py:376} INFO - Running <TaskInstance: rand_user.process_user scheduled__2023-11-09T00:00:00+00:00 [running]> on host 91f7624ceef9
[2023-11-10T09:14:57.342+0000] {taskinstance.py:1592} INFO - Exporting the following env vars:
AIRFLOW_CTX_DAG_OWNER=Gaurav
AIRFLOW_CTX_DAG_ID=rand_user
AIRFLOW_CTX_TASK_ID=process_user
AIRFLOW_CTX_EXECUTION_DATE=2023-11-09T00:00:00+00:00
AIRFLOW_CTX_TRY_NUMBER=3
AIRFLOW_CTX_DAG_RUN_ID=scheduled__2023-11-09T00:00:00+00:00
[2023-11-10T09:14:57.366+0000] {taskinstance.py:1851} ERROR - Task failed with exception
Traceback (most recent call last):
  File "/home/airflow/.local/lib/python3.7/site-packages/airflow/operators/python.py", line 175, in execute
    return_value = self.execute_callable()
  File "/home/airflow/.local/lib/python3.7/site-packages/airflow/operators/python.py", line 193, in execute_callable
    return self.python_callable(*self.op_args, **self.op_kwargs)
  File "/opt/airflow/dags/predictions.py", line 14, in _process_user
    user = user['results'][0]
KeyError: 'results'
[2023-11-10T09:14:57.386+0000] {taskinstance.py:1406} INFO - Marking task as FAILED. dag_id=rand_user, task_id=process_user, execution_date=20231109T000000, start_date=20231110T091457, end_date=20231110T091457
[2023-11-10T09:14:57.411+0000] {standard_task_runner.py:105} ERROR - Failed to execute job 128 for task process_user ('results'; 1932)
[2023-11-10T09:14:57.459+0000] {local_task_job.py:164} INFO - Task exited with return code 1
[2023-11-10T09:14:57.511+0000] {local_task_job.py:273} INFO - 0 downstream tasks scheduled from follow-on schedule check
