[2023-11-10T04:35:52.795+0000] {taskinstance.py:1165} INFO - Dependencies all met for <TaskInstance: US_population.process_user manual__2023-11-10T04:34:43.949783+00:00 [queued]>
[2023-11-10T04:35:52.808+0000] {taskinstance.py:1165} INFO - Dependencies all met for <TaskInstance: US_population.process_user manual__2023-11-10T04:34:43.949783+00:00 [queued]>
[2023-11-10T04:35:52.808+0000] {taskinstance.py:1362} INFO - 
--------------------------------------------------------------------------------
[2023-11-10T04:35:52.809+0000] {taskinstance.py:1363} INFO - Starting attempt 2 of 3
[2023-11-10T04:35:52.809+0000] {taskinstance.py:1364} INFO - 
--------------------------------------------------------------------------------
[2023-11-10T04:35:52.826+0000] {taskinstance.py:1383} INFO - Executing <Task(PythonOperator): process_user> on 2023-11-10 04:34:43.949783+00:00
[2023-11-10T04:35:52.832+0000] {standard_task_runner.py:55} INFO - Started process 1050 to run task
[2023-11-10T04:35:52.837+0000] {standard_task_runner.py:82} INFO - Running: ['***', 'tasks', 'run', 'US_population', 'process_user', 'manual__2023-11-10T04:34:43.949783+00:00', '--job-id', '80', '--raw', '--subdir', 'DAGS_FOLDER/predictions.py', '--cfg-path', '/tmp/tmp3c0rkk7i']
[2023-11-10T04:35:52.840+0000] {standard_task_runner.py:83} INFO - Job 80: Subtask process_user
[2023-11-10T04:35:52.904+0000] {task_command.py:376} INFO - Running <TaskInstance: US_population.process_user manual__2023-11-10T04:34:43.949783+00:00 [running]> on host 91f7624ceef9
[2023-11-10T04:35:52.973+0000] {taskinstance.py:1592} INFO - Exporting the following env vars:
AIRFLOW_CTX_DAG_OWNER=Gaurav
AIRFLOW_CTX_DAG_ID=US_population
AIRFLOW_CTX_TASK_ID=process_user
AIRFLOW_CTX_EXECUTION_DATE=2023-11-10T04:34:43.949783+00:00
AIRFLOW_CTX_TRY_NUMBER=2
AIRFLOW_CTX_DAG_RUN_ID=manual__2023-11-10T04:34:43.949783+00:00
[2023-11-10T04:35:52.986+0000] {taskinstance.py:1851} ERROR - Task failed with exception
Traceback (most recent call last):
  File "/home/airflow/.local/lib/python3.7/site-packages/airflow/operators/python.py", line 175, in execute
    return_value = self.execute_callable()
  File "/home/airflow/.local/lib/python3.7/site-packages/airflow/operators/python.py", line 193, in execute_callable
    return self.python_callable(*self.op_args, **self.op_kwargs)
  File "/opt/airflow/dags/predictions.py", line 28, in _process_user
    if not user_list or not user_list[0]:
KeyError: 0
[2023-11-10T04:35:52.995+0000] {taskinstance.py:1406} INFO - Marking task as UP_FOR_RETRY. dag_id=US_population, task_id=process_user, execution_date=20231110T043443, start_date=20231110T043552, end_date=20231110T043552
[2023-11-10T04:35:53.007+0000] {standard_task_runner.py:105} ERROR - Failed to execute job 80 for task process_user (0; 1050)
[2023-11-10T04:35:53.048+0000] {local_task_job.py:164} INFO - Task exited with return code 1
[2023-11-10T04:35:53.074+0000] {local_task_job.py:273} INFO - 0 downstream tasks scheduled from follow-on schedule check
