[2023-11-22T10:17:18.881+0000] {taskinstance.py:1165} INFO - Dependencies all met for <TaskInstance: Data_transfer.upload_data_source manual__2023-11-22T10:16:06.992462+00:00 [queued]>
[2023-11-22T10:17:18.904+0000] {taskinstance.py:1165} INFO - Dependencies all met for <TaskInstance: Data_transfer.upload_data_source manual__2023-11-22T10:16:06.992462+00:00 [queued]>
[2023-11-22T10:17:18.904+0000] {taskinstance.py:1362} INFO - 
--------------------------------------------------------------------------------
[2023-11-22T10:17:18.905+0000] {taskinstance.py:1363} INFO - Starting attempt 2 of 3
[2023-11-22T10:17:18.905+0000] {taskinstance.py:1364} INFO - 
--------------------------------------------------------------------------------
[2023-11-22T10:17:18.940+0000] {taskinstance.py:1383} INFO - Executing <Task(GenericTransfer): upload_data_source> on 2023-11-22 10:16:06.992462+00:00
[2023-11-22T10:17:18.953+0000] {standard_task_runner.py:55} INFO - Started process 6774 to run task
[2023-11-22T10:17:18.961+0000] {standard_task_runner.py:82} INFO - Running: ['***', 'tasks', 'run', 'Data_transfer', 'upload_data_source', 'manual__2023-11-22T10:16:06.992462+00:00', '--job-id', '179', '--raw', '--subdir', 'DAGS_FOLDER/data_transfer.py', '--cfg-path', '/tmp/tmph5f8b8vv']
[2023-11-22T10:17:18.964+0000] {standard_task_runner.py:83} INFO - Job 179: Subtask upload_data_source
[2023-11-22T10:17:19.075+0000] {task_command.py:376} INFO - Running <TaskInstance: Data_transfer.upload_data_source manual__2023-11-22T10:16:06.992462+00:00 [running]> on host f71f95879a41
[2023-11-22T10:17:19.199+0000] {taskinstance.py:1592} INFO - Exporting the following env vars:
AIRFLOW_CTX_DAG_OWNER=Gaurav
AIRFLOW_CTX_DAG_ID=Data_transfer
AIRFLOW_CTX_TASK_ID=upload_data_source
AIRFLOW_CTX_EXECUTION_DATE=2023-11-22T10:16:06.992462+00:00
AIRFLOW_CTX_TRY_NUMBER=2
AIRFLOW_CTX_DAG_RUN_ID=manual__2023-11-22T10:16:06.992462+00:00
[2023-11-22T10:17:19.215+0000] {base.py:71} INFO - Using connection ID 'postgres' for task execution.
[2023-11-22T10:17:19.482+0000] {base.py:71} INFO - Using connection ID 'source_db_***' for task execution.
[2023-11-22T10:17:19.711+0000] {generic_transfer.py:76} INFO - Extracting data from postgres
[2023-11-22T10:17:19.711+0000] {generic_transfer.py:77} INFO - Executing: 
 SELECT * FROM table1_users
[2023-11-22T10:17:19.718+0000] {base.py:71} INFO - Using connection ID 'postgres' for task execution.
[2023-11-22T10:17:19.724+0000] {generic_transfer.py:104} INFO - Inserting rows into source_db_***
[2023-11-22T10:17:19.730+0000] {base.py:71} INFO - Using connection ID 'source_db_***' for task execution.
[2023-11-22T10:17:19.741+0000] {taskinstance.py:1851} ERROR - Task failed with exception
Traceback (most recent call last):
  File "/home/airflow/.local/lib/python3.7/site-packages/airflow/operators/generic_transfer.py", line 105, in execute
    insert_rows(table=self.destination_table, rows=results, **self.insert_args)
  File "/home/airflow/.local/lib/python3.7/site-packages/airflow/providers/common/sql/hooks/sql.py", line 409, in insert_rows
    cur.execute(sql, values)
psycopg2.errors.UndefinedTable: relation "table1_users" does not exist
LINE 1: INSERT INTO table1_users  VALUES ('3d0212e1-5baa-4430-b868-6...
                    ^

[2023-11-22T10:17:19.750+0000] {taskinstance.py:1406} INFO - Marking task as UP_FOR_RETRY. dag_id=Data_transfer, task_id=upload_data_source, execution_date=20231122T101606, start_date=20231122T101718, end_date=20231122T101719
[2023-11-22T10:17:19.762+0000] {standard_task_runner.py:105} ERROR - Failed to execute job 179 for task upload_data_source (relation "table1_users" does not exist
LINE 1: INSERT INTO table1_users  VALUES ('3d0212e1-5baa-4430-b868-6...
                    ^
; 6774)
[2023-11-22T10:17:19.813+0000] {local_task_job.py:164} INFO - Task exited with return code 1
[2023-11-22T10:17:19.847+0000] {local_task_job.py:273} INFO - 0 downstream tasks scheduled from follow-on schedule check
