[2023-11-23T06:26:32.091+0000] {taskinstance.py:1165} INFO - Dependencies all met for <TaskInstance: rand_user.process_user manual__2023-11-23T06:26:24.430075+00:00 [queued]>
[2023-11-23T06:26:32.105+0000] {taskinstance.py:1165} INFO - Dependencies all met for <TaskInstance: rand_user.process_user manual__2023-11-23T06:26:24.430075+00:00 [queued]>
[2023-11-23T06:26:32.105+0000] {taskinstance.py:1362} INFO - 
--------------------------------------------------------------------------------
[2023-11-23T06:26:32.106+0000] {taskinstance.py:1363} INFO - Starting attempt 1 of 3
[2023-11-23T06:26:32.106+0000] {taskinstance.py:1364} INFO - 
--------------------------------------------------------------------------------
[2023-11-23T06:26:32.124+0000] {taskinstance.py:1383} INFO - Executing <Task(PythonOperator): process_user> on 2023-11-23 06:26:24.430075+00:00
[2023-11-23T06:26:32.130+0000] {standard_task_runner.py:55} INFO - Started process 6873 to run task
[2023-11-23T06:26:32.135+0000] {standard_task_runner.py:82} INFO - Running: ['***', 'tasks', 'run', 'rand_user', 'process_user', 'manual__2023-11-23T06:26:24.430075+00:00', '--job-id', '481', '--raw', '--subdir', 'DAGS_FOLDER/predictions.py', '--cfg-path', '/tmp/tmponrblegn']
[2023-11-23T06:26:32.137+0000] {standard_task_runner.py:83} INFO - Job 481: Subtask process_user
[2023-11-23T06:26:32.206+0000] {task_command.py:376} INFO - Running <TaskInstance: rand_user.process_user manual__2023-11-23T06:26:24.430075+00:00 [running]> on host f71f95879a41
[2023-11-23T06:26:32.282+0000] {taskinstance.py:1592} INFO - Exporting the following env vars:
AIRFLOW_CTX_DAG_OWNER=Gaurav
AIRFLOW_CTX_DAG_ID=rand_user
AIRFLOW_CTX_TASK_ID=process_user
AIRFLOW_CTX_EXECUTION_DATE=2023-11-23T06:26:24.430075+00:00
AIRFLOW_CTX_TRY_NUMBER=1
AIRFLOW_CTX_DAG_RUN_ID=manual__2023-11-23T06:26:24.430075+00:00
[2023-11-23T06:26:32.296+0000] {taskinstance.py:1851} ERROR - Task failed with exception
Traceback (most recent call last):
  File "/home/airflow/.local/lib/python3.7/site-packages/airflow/operators/python.py", line 175, in execute
    return_value = self.execute_callable()
  File "/home/airflow/.local/lib/python3.7/site-packages/airflow/operators/python.py", line 193, in execute_callable
    return self.python_callable(*self.op_args, **self.op_kwargs)
  File "/opt/airflow/dags/predictions.py", line 15, in _process_user
    user = user_data['results'][0]
TypeError: string indices must be integers
[2023-11-23T06:26:32.305+0000] {taskinstance.py:1406} INFO - Marking task as UP_FOR_RETRY. dag_id=rand_user, task_id=process_user, execution_date=20231123T062624, start_date=20231123T062632, end_date=20231123T062632
[2023-11-23T06:26:32.316+0000] {standard_task_runner.py:105} ERROR - Failed to execute job 481 for task process_user (string indices must be integers; 6873)
[2023-11-23T06:26:32.346+0000] {local_task_job.py:164} INFO - Task exited with return code 1
[2023-11-23T06:26:32.396+0000] {local_task_job.py:273} INFO - 0 downstream tasks scheduled from follow-on schedule check
