[2023-11-14T10:40:32.021+0000] {taskinstance.py:1165} INFO - Dependencies all met for <TaskInstance: rand_user.upload_data_source manual__2023-11-14T10:40:20.530545+00:00 [queued]>
[2023-11-14T10:40:32.032+0000] {taskinstance.py:1165} INFO - Dependencies all met for <TaskInstance: rand_user.upload_data_source manual__2023-11-14T10:40:20.530545+00:00 [queued]>
[2023-11-14T10:40:32.033+0000] {taskinstance.py:1362} INFO - 
--------------------------------------------------------------------------------
[2023-11-14T10:40:32.033+0000] {taskinstance.py:1363} INFO - Starting attempt 1 of 3
[2023-11-14T10:40:32.033+0000] {taskinstance.py:1364} INFO - 
--------------------------------------------------------------------------------
[2023-11-14T10:40:32.049+0000] {taskinstance.py:1383} INFO - Executing <Task(GenericTransfer): upload_data_source> on 2023-11-14 10:40:20.530545+00:00
[2023-11-14T10:40:32.056+0000] {standard_task_runner.py:55} INFO - Started process 3965 to run task
[2023-11-14T10:40:32.061+0000] {standard_task_runner.py:82} INFO - Running: ['***', 'tasks', 'run', 'rand_user', 'upload_data_source', 'manual__2023-11-14T10:40:20.530545+00:00', '--job-id', '451', '--raw', '--subdir', 'DAGS_FOLDER/predictions.py', '--cfg-path', '/tmp/tmp0yvls17s']
[2023-11-14T10:40:32.063+0000] {standard_task_runner.py:83} INFO - Job 451: Subtask upload_data_source
[2023-11-14T10:40:32.129+0000] {task_command.py:376} INFO - Running <TaskInstance: rand_user.upload_data_source manual__2023-11-14T10:40:20.530545+00:00 [running]> on host 91f7624ceef9
[2023-11-14T10:40:32.199+0000] {taskinstance.py:1592} INFO - Exporting the following env vars:
AIRFLOW_CTX_DAG_OWNER=Gaurav
AIRFLOW_CTX_DAG_ID=rand_user
AIRFLOW_CTX_TASK_ID=upload_data_source
AIRFLOW_CTX_EXECUTION_DATE=2023-11-14T10:40:20.530545+00:00
AIRFLOW_CTX_TRY_NUMBER=1
AIRFLOW_CTX_DAG_RUN_ID=manual__2023-11-14T10:40:20.530545+00:00
[2023-11-14T10:40:32.218+0000] {taskinstance.py:1851} ERROR - Task failed with exception
Traceback (most recent call last):
  File "/home/airflow/.local/lib/python3.7/site-packages/airflow/operators/generic_transfer.py", line 73, in execute
    source_hook = BaseHook.get_hook(self.source_conn_id)
  File "/home/airflow/.local/lib/python3.7/site-packages/airflow/hooks/base.py", line 84, in get_hook
    connection = cls.get_connection(conn_id)
  File "/home/airflow/.local/lib/python3.7/site-packages/airflow/hooks/base.py", line 70, in get_connection
    conn = Connection.get_connection_from_secrets(conn_id)
  File "/home/airflow/.local/lib/python3.7/site-packages/airflow/models/connection.py", line 432, in get_connection_from_secrets
    raise AirflowNotFoundException(f"The conn_id `{conn_id}` isn't defined")
airflow.exceptions.AirflowNotFoundException: The conn_id `postgres` isn't defined
[2023-11-14T10:40:32.223+0000] {taskinstance.py:1406} INFO - Marking task as UP_FOR_RETRY. dag_id=rand_user, task_id=upload_data_source, execution_date=20231114T104020, start_date=20231114T104032, end_date=20231114T104032
[2023-11-14T10:40:32.234+0000] {standard_task_runner.py:105} ERROR - Failed to execute job 451 for task upload_data_source (The conn_id `postgres` isn't defined; 3965)
[2023-11-14T10:40:32.272+0000] {local_task_job.py:164} INFO - Task exited with return code 1
[2023-11-14T10:40:32.297+0000] {local_task_job.py:273} INFO - 0 downstream tasks scheduled from follow-on schedule check
