[2023-11-10T04:33:03.689+0000] {taskinstance.py:1165} INFO - Dependencies all met for <TaskInstance: US_population.process_user manual__2023-11-10T04:30:55.118621+00:00 [queued]>
[2023-11-10T04:33:03.703+0000] {taskinstance.py:1165} INFO - Dependencies all met for <TaskInstance: US_population.process_user manual__2023-11-10T04:30:55.118621+00:00 [queued]>
[2023-11-10T04:33:03.703+0000] {taskinstance.py:1362} INFO - 
--------------------------------------------------------------------------------
[2023-11-10T04:33:03.704+0000] {taskinstance.py:1363} INFO - Starting attempt 3 of 3
[2023-11-10T04:33:03.704+0000] {taskinstance.py:1364} INFO - 
--------------------------------------------------------------------------------
[2023-11-10T04:33:03.720+0000] {taskinstance.py:1383} INFO - Executing <Task(PythonOperator): process_user> on 2023-11-10 04:30:55.118621+00:00
[2023-11-10T04:33:03.726+0000] {standard_task_runner.py:55} INFO - Started process 900 to run task
[2023-11-10T04:33:03.731+0000] {standard_task_runner.py:82} INFO - Running: ['***', 'tasks', 'run', 'US_population', 'process_user', 'manual__2023-11-10T04:30:55.118621+00:00', '--job-id', '75', '--raw', '--subdir', 'DAGS_FOLDER/predictions.py', '--cfg-path', '/tmp/tmp_rq_ka20']
[2023-11-10T04:33:03.733+0000] {standard_task_runner.py:83} INFO - Job 75: Subtask process_user
[2023-11-10T04:33:03.795+0000] {task_command.py:376} INFO - Running <TaskInstance: US_population.process_user manual__2023-11-10T04:30:55.118621+00:00 [running]> on host 91f7624ceef9
[2023-11-10T04:33:03.865+0000] {taskinstance.py:1592} INFO - Exporting the following env vars:
AIRFLOW_CTX_DAG_OWNER=Gaurav
AIRFLOW_CTX_DAG_ID=US_population
AIRFLOW_CTX_TASK_ID=process_user
AIRFLOW_CTX_EXECUTION_DATE=2023-11-10T04:30:55.118621+00:00
AIRFLOW_CTX_TRY_NUMBER=3
AIRFLOW_CTX_DAG_RUN_ID=manual__2023-11-10T04:30:55.118621+00:00
[2023-11-10T04:33:03.878+0000] {taskinstance.py:1851} ERROR - Task failed with exception
Traceback (most recent call last):
  File "/home/airflow/.local/lib/python3.7/site-packages/airflow/operators/python.py", line 175, in execute
    return_value = self.execute_callable()
  File "/home/airflow/.local/lib/python3.7/site-packages/airflow/operators/python.py", line 193, in execute_callable
    return self.python_callable(*self.op_args, **self.op_kwargs)
  File "/opt/airflow/dags/predictions.py", line 36, in _process_user
    'ID_Nation': user_list['ID Nation'],
KeyError: 'ID Nation'
[2023-11-10T04:33:03.889+0000] {taskinstance.py:1406} INFO - Marking task as FAILED. dag_id=US_population, task_id=process_user, execution_date=20231110T043055, start_date=20231110T043303, end_date=20231110T043303
[2023-11-10T04:33:03.903+0000] {standard_task_runner.py:105} ERROR - Failed to execute job 75 for task process_user ('ID Nation'; 900)
[2023-11-10T04:33:03.941+0000] {local_task_job.py:164} INFO - Task exited with return code 1
[2023-11-10T04:33:03.970+0000] {local_task_job.py:273} INFO - 0 downstream tasks scheduled from follow-on schedule check
